2024-05-10 06:48:38,891 ERROR: Exception on /create_challenge [POST] [in C:\Users\HP Laptop\AppData\Local\Programs\Python\Python312\Lib\site-packages\flask\app.py:838]
Traceback (most recent call last):
  File "C:\Users\HP Laptop\AppData\Local\Programs\Python\Python312\Lib\site-packages\flask\app.py", line 1473, in wsgi_app
    response = self.full_dispatch_request()
               ^^^^^^^^^^^^^^^^^^^^^^^^^^^^
  File "C:\Users\HP Laptop\AppData\Local\Programs\Python\Python312\Lib\site-packages\flask\app.py", line 882, in full_dispatch_request
    rv = self.handle_user_exception(e)
         ^^^^^^^^^^^^^^^^^^^^^^^^^^^^^
  File "C:\Users\HP Laptop\AppData\Local\Programs\Python\Python312\Lib\site-packages\flask\app.py", line 880, in full_dispatch_request
    rv = self.dispatch_request()
         ^^^^^^^^^^^^^^^^^^^^^^^
  File "C:\Users\HP Laptop\AppData\Local\Programs\Python\Python312\Lib\site-packages\flask\app.py", line 865, in dispatch_request
    return self.ensure_sync(self.view_functions[rule.endpoint])(**view_args)  # type: ignore[no-any-return]
           ^^^^^^^^^^^^^^^^^^^^^^^^^^^^^^^^^^^^^^^^^^^^^^^^^^^^^^^^^^^^^^^^^
  File "C:\Users\HP Laptop\Desktop\game\cits3403\app\routes.py", line 68, in create_challenge
    return redirect(url_for('/create_challenge'))
                    ^^^^^^^^^^^^^^^^^^^^^^^^^^^^
  File "C:\Users\HP Laptop\AppData\Local\Programs\Python\Python312\Lib\site-packages\flask\helpers.py", line 220, in url_for
    return current_app.url_for(
           ^^^^^^^^^^^^^^^^^^^^
  File "C:\Users\HP Laptop\AppData\Local\Programs\Python\Python312\Lib\site-packages\flask\app.py", line 1084, in url_for
    return self.handle_url_build_error(error, endpoint, values)
           ^^^^^^^^^^^^^^^^^^^^^^^^^^^^^^^^^^^^^^^^^^^^^^^^^^^^
  File "C:\Users\HP Laptop\AppData\Local\Programs\Python\Python312\Lib\site-packages\flask\app.py", line 1073, in url_for
    rv = url_adapter.build(  # type: ignore[union-attr]
         ^^^^^^^^^^^^^^^^^^^^^^^^^^^^^^^^^^^^^^^^^^^^^^
  File "C:\Users\HP Laptop\AppData\Local\Programs\Python\Python312\Lib\site-packages\werkzeug\routing\map.py", line 926, in build
    raise BuildError(endpoint, values, method, self)
werkzeug.routing.exceptions.BuildError: Could not build url for endpoint '/create_challenge'. Did you mean 'create_challenge' instead?
2024-05-10 06:49:13,635 ERROR: Exception on /create_challenge [POST] [in C:\Users\HP Laptop\AppData\Local\Programs\Python\Python312\Lib\site-packages\flask\app.py:838]
Traceback (most recent call last):
  File "C:\Users\HP Laptop\AppData\Local\Programs\Python\Python312\Lib\site-packages\flask\app.py", line 1473, in wsgi_app
    response = self.full_dispatch_request()
               ^^^^^^^^^^^^^^^^^^^^^^^^^^^^
  File "C:\Users\HP Laptop\AppData\Local\Programs\Python\Python312\Lib\site-packages\flask\app.py", line 882, in full_dispatch_request
    rv = self.handle_user_exception(e)
         ^^^^^^^^^^^^^^^^^^^^^^^^^^^^^
  File "C:\Users\HP Laptop\AppData\Local\Programs\Python\Python312\Lib\site-packages\flask\app.py", line 880, in full_dispatch_request
    rv = self.dispatch_request()
         ^^^^^^^^^^^^^^^^^^^^^^^
  File "C:\Users\HP Laptop\AppData\Local\Programs\Python\Python312\Lib\site-packages\flask\app.py", line 865, in dispatch_request
    return self.ensure_sync(self.view_functions[rule.endpoint])(**view_args)  # type: ignore[no-any-return]
           ^^^^^^^^^^^^^^^^^^^^^^^^^^^^^^^^^^^^^^^^^^^^^^^^^^^^^^^^^^^^^^^^^
  File "C:\Users\HP Laptop\Desktop\game\cits3403\app\routes.py", line 68, in create_challenge
    return redirect(url_for('/create_challenge'))
                    ^^^^^^^^^^^^^^^^^^^^^^^^^^^^
  File "C:\Users\HP Laptop\AppData\Local\Programs\Python\Python312\Lib\site-packages\flask\helpers.py", line 220, in url_for
    return current_app.url_for(
           ^^^^^^^^^^^^^^^^^^^^
  File "C:\Users\HP Laptop\AppData\Local\Programs\Python\Python312\Lib\site-packages\flask\app.py", line 1084, in url_for
    return self.handle_url_build_error(error, endpoint, values)
           ^^^^^^^^^^^^^^^^^^^^^^^^^^^^^^^^^^^^^^^^^^^^^^^^^^^^
  File "C:\Users\HP Laptop\AppData\Local\Programs\Python\Python312\Lib\site-packages\flask\app.py", line 1073, in url_for
    rv = url_adapter.build(  # type: ignore[union-attr]
         ^^^^^^^^^^^^^^^^^^^^^^^^^^^^^^^^^^^^^^^^^^^^^^
  File "C:\Users\HP Laptop\AppData\Local\Programs\Python\Python312\Lib\site-packages\werkzeug\routing\map.py", line 926, in build
    raise BuildError(endpoint, values, method, self)
werkzeug.routing.exceptions.BuildError: Could not build url for endpoint '/create_challenge'. Did you mean 'create_challenge' instead?
2024-05-10 06:49:43,922 ERROR: Exception on /create_challenge [POST] [in C:\Users\HP Laptop\AppData\Local\Programs\Python\Python312\Lib\site-packages\flask\app.py:838]
Traceback (most recent call last):
  File "C:\Users\HP Laptop\AppData\Local\Programs\Python\Python312\Lib\site-packages\flask\app.py", line 1473, in wsgi_app
    response = self.full_dispatch_request()
               ^^^^^^^^^^^^^^^^^^^^^^^^^^^^
  File "C:\Users\HP Laptop\AppData\Local\Programs\Python\Python312\Lib\site-packages\flask\app.py", line 882, in full_dispatch_request
    rv = self.handle_user_exception(e)
         ^^^^^^^^^^^^^^^^^^^^^^^^^^^^^
  File "C:\Users\HP Laptop\AppData\Local\Programs\Python\Python312\Lib\site-packages\flask\app.py", line 880, in full_dispatch_request
    rv = self.dispatch_request()
         ^^^^^^^^^^^^^^^^^^^^^^^
  File "C:\Users\HP Laptop\AppData\Local\Programs\Python\Python312\Lib\site-packages\flask\app.py", line 865, in dispatch_request
    return self.ensure_sync(self.view_functions[rule.endpoint])(**view_args)  # type: ignore[no-any-return]
           ^^^^^^^^^^^^^^^^^^^^^^^^^^^^^^^^^^^^^^^^^^^^^^^^^^^^^^^^^^^^^^^^^
  File "C:\Users\HP Laptop\Desktop\game\cits3403\app\routes.py", line 68, in create_challenge
    return redirect(url_for('/create_challenge'))
                    ^^^^^^^^^^^^^^^^^^^^^^^^^^^^
  File "C:\Users\HP Laptop\AppData\Local\Programs\Python\Python312\Lib\site-packages\flask\helpers.py", line 220, in url_for
    return current_app.url_for(
           ^^^^^^^^^^^^^^^^^^^^
  File "C:\Users\HP Laptop\AppData\Local\Programs\Python\Python312\Lib\site-packages\flask\app.py", line 1084, in url_for
    return self.handle_url_build_error(error, endpoint, values)
           ^^^^^^^^^^^^^^^^^^^^^^^^^^^^^^^^^^^^^^^^^^^^^^^^^^^^
  File "C:\Users\HP Laptop\AppData\Local\Programs\Python\Python312\Lib\site-packages\flask\app.py", line 1073, in url_for
    rv = url_adapter.build(  # type: ignore[union-attr]
         ^^^^^^^^^^^^^^^^^^^^^^^^^^^^^^^^^^^^^^^^^^^^^^
  File "C:\Users\HP Laptop\AppData\Local\Programs\Python\Python312\Lib\site-packages\werkzeug\routing\map.py", line 926, in build
    raise BuildError(endpoint, values, method, self)
werkzeug.routing.exceptions.BuildError: Could not build url for endpoint '/create_challenge'. Did you mean 'create_challenge' instead?
2024-05-10 06:50:15,125 ERROR: Exception on /create_challenge [POST] [in C:\Users\HP Laptop\AppData\Local\Programs\Python\Python312\Lib\site-packages\flask\app.py:838]
Traceback (most recent call last):
  File "C:\Users\HP Laptop\AppData\Local\Programs\Python\Python312\Lib\site-packages\flask\app.py", line 1473, in wsgi_app
    response = self.full_dispatch_request()
               ^^^^^^^^^^^^^^^^^^^^^^^^^^^^
  File "C:\Users\HP Laptop\AppData\Local\Programs\Python\Python312\Lib\site-packages\flask\app.py", line 882, in full_dispatch_request
    rv = self.handle_user_exception(e)
         ^^^^^^^^^^^^^^^^^^^^^^^^^^^^^
  File "C:\Users\HP Laptop\AppData\Local\Programs\Python\Python312\Lib\site-packages\flask\app.py", line 880, in full_dispatch_request
    rv = self.dispatch_request()
         ^^^^^^^^^^^^^^^^^^^^^^^
  File "C:\Users\HP Laptop\AppData\Local\Programs\Python\Python312\Lib\site-packages\flask\app.py", line 865, in dispatch_request
    return self.ensure_sync(self.view_functions[rule.endpoint])(**view_args)  # type: ignore[no-any-return]
           ^^^^^^^^^^^^^^^^^^^^^^^^^^^^^^^^^^^^^^^^^^^^^^^^^^^^^^^^^^^^^^^^^
  File "C:\Users\HP Laptop\Desktop\game\cits3403\app\routes.py", line 68, in create_challenge
    return redirect(url_for('/create_challenge'))
                    ^^^^^^^^^^^^^^^^^^^^^^^^^^^^
  File "C:\Users\HP Laptop\AppData\Local\Programs\Python\Python312\Lib\site-packages\flask\helpers.py", line 220, in url_for
    return current_app.url_for(
           ^^^^^^^^^^^^^^^^^^^^
  File "C:\Users\HP Laptop\AppData\Local\Programs\Python\Python312\Lib\site-packages\flask\app.py", line 1084, in url_for
    return self.handle_url_build_error(error, endpoint, values)
           ^^^^^^^^^^^^^^^^^^^^^^^^^^^^^^^^^^^^^^^^^^^^^^^^^^^^
  File "C:\Users\HP Laptop\AppData\Local\Programs\Python\Python312\Lib\site-packages\flask\app.py", line 1073, in url_for
    rv = url_adapter.build(  # type: ignore[union-attr]
         ^^^^^^^^^^^^^^^^^^^^^^^^^^^^^^^^^^^^^^^^^^^^^^
  File "C:\Users\HP Laptop\AppData\Local\Programs\Python\Python312\Lib\site-packages\werkzeug\routing\map.py", line 926, in build
    raise BuildError(endpoint, values, method, self)
werkzeug.routing.exceptions.BuildError: Could not build url for endpoint '/create_challenge'. Did you mean 'create_challenge' instead?
2024-05-10 06:55:47,527 INFO: Microblog startup [in C:\Users\HP Laptop\Desktop\game\cits3403\app\__init__.py:46]
2024-05-10 07:08:25,636 INFO: Microblog startup [in C:\Users\HP Laptop\Desktop\game\cits3403\app\__init__.py:46]
2024-05-10 07:10:00,496 INFO: Microblog startup [in C:\Users\HP Laptop\Desktop\game\cits3403\app\__init__.py:46]
2024-05-10 07:11:27,250 INFO: Microblog startup [in C:\Users\HP Laptop\Desktop\game\cits3403\app\__init__.py:46]
2024-05-10 07:12:25,273 INFO: Microblog startup [in C:\Users\HP Laptop\Desktop\game\cits3403\app\__init__.py:46]
2024-05-10 07:20:49,362 INFO: Microblog startup [in C:\Users\HP Laptop\Desktop\game\cits3403\app\__init__.py:46]
2024-05-10 07:22:11,130 INFO: Microblog startup [in C:\Users\HP Laptop\Desktop\game\cits3403\app\__init__.py:46]
