2024-04-24 22:34:20,253 INFO: Microblog startup [in /Users/hoiyensha/rock paper/cits3403/app/__init__.py:46]
2024-05-09 07:58:51,279 INFO: Microblog startup [in /workspaces/cits3403/app/__init__.py:46]
2024-05-09 07:59:33,020 INFO: Microblog startup [in /workspaces/cits3403/app/__init__.py:46]
2024-05-09 08:00:05,302 INFO: Microblog startup [in /workspaces/cits3403/app/__init__.py:46]
2024-05-09 08:06:33,857 INFO: Microblog startup [in /workspaces/cits3403/app/__init__.py:46]
2024-05-09 08:18:16,734 INFO: Microblog startup [in /workspaces/cits3403/app/__init__.py:46]
2024-05-09 10:15:59,872 INFO: Microblog startup [in /workspaces/cits3403/app/__init__.py:46]
2024-05-09 10:19:53,701 INFO: Microblog startup [in /workspaces/cits3403/app/__init__.py:46]
2024-05-09 10:47:30,661 INFO: Microblog startup [in /workspaces/cits3403/app/__init__.py:45]
2024-05-09 10:48:15,855 INFO: Microblog startup [in /workspaces/cits3403/app/__init__.py:45]
2024-05-09 10:49:09,922 INFO: Microblog startup [in /workspaces/cits3403/app/__init__.py:45]
2024-05-09 10:51:26,895 INFO: Microblog startup [in /workspaces/cits3403/app/__init__.py:45]
2024-05-09 10:52:47,544 INFO: Microblog startup [in /workspaces/cits3403/app/__init__.py:45]
2024-05-09 10:53:39,492 INFO: Microblog startup [in /workspaces/cits3403/app/__init__.py:45]
2024-05-09 10:54:06,823 ERROR: Exception on /register [POST] [in /usr/local/python/3.10.13/lib/python3.10/site-packages/flask/app.py:838]
Traceback (most recent call last):
  File "/usr/local/python/3.10.13/lib/python3.10/site-packages/wtforms/validators.py", line 401, in __call__
    import email_validator
ModuleNotFoundError: No module named 'email_validator'

The above exception was the direct cause of the following exception:

Traceback (most recent call last):
  File "/usr/local/python/3.10.13/lib/python3.10/site-packages/flask/app.py", line 1473, in wsgi_app
    response = self.full_dispatch_request()
  File "/usr/local/python/3.10.13/lib/python3.10/site-packages/flask/app.py", line 882, in full_dispatch_request
    rv = self.handle_user_exception(e)
  File "/usr/local/python/3.10.13/lib/python3.10/site-packages/flask/app.py", line 880, in full_dispatch_request
    rv = self.dispatch_request()
  File "/usr/local/python/3.10.13/lib/python3.10/site-packages/flask/app.py", line 865, in dispatch_request
    return self.ensure_sync(self.view_functions[rule.endpoint])(**view_args)  # type: ignore[no-any-return]
  File "/workspaces/cits3403/app/routes.py", line 55, in register
    if form.validate_on_submit():
  File "/usr/local/python/3.10.13/lib/python3.10/site-packages/flask_wtf/form.py", line 86, in validate_on_submit
    return self.is_submitted() and self.validate(extra_validators=extra_validators)
  File "/usr/local/python/3.10.13/lib/python3.10/site-packages/wtforms/form.py", line 329, in validate
    return super().validate(extra)
  File "/usr/local/python/3.10.13/lib/python3.10/site-packages/wtforms/form.py", line 146, in validate
    if not field.validate(self, extra):
  File "/usr/local/python/3.10.13/lib/python3.10/site-packages/wtforms/fields/core.py", line 246, in validate
    stop_validation = self._run_validation_chain(form, chain)
  File "/usr/local/python/3.10.13/lib/python3.10/site-packages/wtforms/fields/core.py", line 266, in _run_validation_chain
    validator(form, self)
  File "/usr/local/python/3.10.13/lib/python3.10/site-packages/wtforms/validators.py", line 403, in __call__
    raise Exception(
Exception: Install 'email_validator' for email validation support.
2024-05-09 10:54:40,017 INFO: Microblog startup [in /workspaces/cits3403/app/__init__.py:45]
2024-05-09 11:17:38,236 INFO: Microblog startup [in /workspaces/cits3403/app/__init__.py:45]
